Workbook

Sheet 表注
A1: 表头对应 | D1: 深部溃疡
A2: 患者编号 | B2: Title字段中含有括号的部分 | D2: Yes | E2: 1
A3: 取样部位 | B3: tissue | D3: No | E3: 0
A4: 性别 | B4: Sex
A5: 年龄（诊断入组时） | B5: age at diagnosis
A6: Paris分期 | B6: paris age
A7: IBD疾病类型 | B7: diagnosis
A8: IBD疾病细分类型 | B8: l2 type
A9: 组织病理学特征 | B9: histopathology
A10: 深部溃疡 | B10: deep ulcer

Sheet RISK进展队列GEO回末测序数据整理
A1: GSM编号 | B1: 患者编号 | C1: 取样部位 | D1: 性别 | E1: 年龄（诊断入组时） | F1: Paris分期 | G1: IBD疾病类型 | H1: IBD疾病细分类型 | I1: 组织病理学特征 | J1: 深部溃疡
A2: GSM1598408 | B2: CCFA_Risk_001 | C2: Ileum（回肠） | D2: 女 | E2: 15.25 | F2: A1b | G2: CD | H2: iCD | I2: Macroscopic inflammation | J2: 0
A3: GSM1598409 | B3: CCFA_Risk_002 | C3: Ileum（回肠） | D3: 男 | E3: 14.42 | F3: A1b | G3: CD | H3: iCD | I3: Macroscopic inflammation | J3: 0
A4: GSM1598410 | B4: CCFA_Risk_003 | C4: Ileum（回肠） | D4: 女 | E4: 12.5 | F4: A1b | G4: CD | H4: iCD | I4: Macroscopic inflammation | J4: 0
A5: GSM1598411 | B5: CCFA_Risk_004 | C5: Ileum（回肠） | D5: 男 | E5: 14.58 | F5: A1b | G5: CD | H5: iCD | I5: Macroscopic inflammation | J5: 0
A6: GSM1598412 | B6: CCFA_Risk_005 | C6: Ileum（回肠） | D6: 女 | E6: 10.17 | F6: A1b | G6: CD | H6: iCD | I6: Macroscopic inflammation | J6: 0
A7: GSM1598413 | B7: CCFA_Risk_006 | C7: Ileum（回肠） | D7: 女 | E7: 15.75 | F7: A1b | G7: CD | H7: iCD | I7: Macroscopic inflammation | J7: 1
A8: GSM1598414 | B8: CCFA_Risk_007 | C8: Ileum（回肠） | D8: 男 | E8: 14.33 | F8: A1b | G8: CD | H8: iCD | I8: Macroscopic inflammation | J8: 0
A9: GSM1598415 | B9: CCFA_Risk_008 | C9: Ileum（回肠） | D9: 男 | E9: 11.42 | F9: A1b | G9: CD | H9: cCD | I9: Normal | J9: 0
A10: GSM1598416 | B10: CCFA_Risk_009 | C10: Ileum（回肠） | D10: 女 | E10: 9 | F10: A1a | G10: CD | H10: iCD | I10: Macroscopic inflammation | J10: 0
A11: GSM1598417 | B11: CCFA_Risk_010 | C11: Ileum（回肠） | D11: 男 | E11: 10.33 | F11: A1b | G11: Not IBD | H11: Not IBD | I11: NA | J11: NA
A12: GSM1598418 | B12: CCFA_Risk_011 | C12: Ileum（回肠） | D12: 男 | E12: 10.83 | F12: A1b | G12: Not IBD | H12: Not IBD | I12: NA | J12: NA
A13: GSM1598419 | B13: CCFA_Risk_012 | C13: Ileum（回肠） | D13: 女 | E13: 13.92 | F13: A1b | G13: CD | H13: cCD | I13: Microscopic inflammation | J13: 0
A14: GSM1598420 | B14: CCFA_Risk_013 | C14: Ileum（回肠） | D14: 男 | E14: 9.25 | F14: A1a | G14: CD | H14: iCD | I14: Macroscopic inflammation | J14: 0
A15: GSM1598421 | B15: CCFA_Risk_014 | C15: Ileum（回肠） | D15: 女 | E15: 9 | F15: A1a | G15: Not IBD | H15: Not IBD | I15: NA | J15: NA
A16: GSM1598422 | B16: CCFA_Risk_015 | C16: Ileum（回肠） | D16: 男 | E16: 13.42 | F16: A1b | G16: CD | H16: iCD | I16: Macroscopic inflammation | J16: 0
A17: GSM1598423 | B17: CCFA_Risk_016 | C17: Ileum（回肠） | D17: 男 | E17: 15.17 | F17: A1b | G17: CD | H17: iCD | I17: Macroscopic inflammation | J17: 0
A18: GSM1598424 | B18: CCFA_Risk_017 | C18: Ileum（回肠） | D18: 男 | E18: 13.25 | F18: A1b | G18: CD | H18: iCD | I18: Macroscopic inflammation | J18: 1
A19: GSM1598425 | B19: CCFA_Risk_018 | C19: Ileum（回肠） | D19: 女 | E19: 16.08 | F19: A1b | G19: CD | H19: iCD | I19: Macroscopic inflammation | J19: 0
A20: GSM1598426 | B20: CCFA_Risk_019 | C20: Ileum（回肠） | D20: 女 | E20: 15 | F20: A1b | G20: Not IBD | H20: Not IBD | I20: NA | J20: NA
A21: GSM1598427 | B21: CCFA_Risk_020 | C21: Ileum（回肠） | D21: 女 | E21: 10.75 | F21: A1b | G21: not IBD | H21: not IBD | I21: NA | J21: NA
A22: GSM1598428 | B22: CCFA_Risk_021 | C22: Ileum（回肠） | D22: 男 | E22: 10.33 | F22: A1b | G22: CD | H22: iCD | I22: Macroscopic inflammation | J22: 1
A23: GSM1598429 | B23: CCFA_Risk_022 | C23: Ileum（回肠） | D23: 女 | E23: 10.83 | F23: A1b | G23: CD | H23: iCD | I23: Macroscopic inflammation | J23: 1
A24: GSM1598430 | B24: CCFA_Risk_023 | C24: Ileum（回肠） | D24: 女 | E24: 10.17 | F24: A1b | G24: CD | H24: iCD | I24: Macroscopic inflammation | J24: 1
A25: GSM1598431 | B25: CCFA_Risk_024 | C25: Ileum（回肠） | D25: 男 | E25: 4.5 | F25: A1a | G25: CD | H25: iCD | I25: Macroscopic inflammation | J25: 0
A26: GSM1598432 | B26: CCFA_Risk_025 | C26: Ileum（回肠） | D26: 女 | E26: 6.33 | F26: A1a | G26: CD | H26: iCD | I26: Macroscopic inflammation | J26: 0
A27: GSM1598433 | B27: CCFA_Risk_026 | C27: Ileum（回肠） | D27: 男 | E27: 5.08 | F27: A1a | G27: CD | H27: iCD | I27: Macroscopic inflammation | J27: 0
A28: GSM1598434 | B28: CCFA_Risk_027 | C28: Ileum（回肠） | D28: 女 | E28: 10.33 | F28: A1b | G28: CD | H28: iCD | I28: Macroscopic inflammation | J28: 1
A29: GSM1598435 | B29: CCFA_Risk_028 | C29: Ileum（回肠） | D29: 女 | E29: 16.92 | F29: A1b | G29: Not IBD | H29: Not IBD | I29: NA | J29: NA
A30: GSM1598436 | B30: CCFA_Risk_029 | C30: Ileum（回肠） | D30: 女 | E30: 10.83 | F30: A1b | G30: CD | H30: iCD | I30: Macroscopic inflammation | J30: 0
A31: GSM1598437 | B31: CCFA_Risk_030 | C31: Ileum（回肠） | D31: 男 | E31: 10.75 | F31: A1b | G31: CD | H31: iCD | I31: Macroscopic inflammation | J31: 0
A32: GSM1598438 | B32: CCFA_Risk_031 | C32: Ileum（回肠） | D32: 女 | E32: 12.5 | F32: A1b | G32: Not IBD | H32: Not IBD | I32: NA | J32: NA
A33: GSM1598439 | B33: CCFA_Risk_032 | C33: Ileum（回肠） | D33: 女 | E33: 8.67 | F33: A1a | G33: CD | H33: iCD | I33: Macroscopic inflammation | J33: 0
A34: GSM1598440 | B34: CCFA_Risk_033 | C34: Ileum（回肠） | D34: 男 | E34: 9.33 | F34: A1a | G34: Not IBD | H34: Not IBD | I34: NA | J34: NA
A35: GSM1598441 | B35: CCFA_Risk_034 | C35: Ileum（回肠） | D35: 男 | E35: 7.75 | F35: A1a | G35: Not IBD | H35: Not IBD | I35: NA | J35: NA
A36: GSM1598442 | B36: CCFA_Risk_035 | C36: Ileum（回肠） | D36: 男 | E36: 11.5 | F36: A1b | G36: Not IBD | H36: Not IBD | I36: NA | J36: NA
A37: GSM1598443 | B37: CCFA_Risk_036 | C37: Ileum（回肠） | D37: 男 | E37: 10.5 | F37: A1b | G37: Not IBD | H37: Not IBD | I37: NA | J37: NA
A38: GSM1598444 | B38: CCFA_Risk_037 | C38: Ileum（回肠） | D38: 男 | E38: 10.5 | F38: A1b | G38: CD | H38: iCD | I38: Macroscopic inflammation | J38: 1
A39: GSM1598445 | B39: CCFA_Risk_038 | C39: Ileum（回肠） | D39: 男 | E39: 8.67 | F39: A1a | G39: Not IBD | H39: Not IBD | I39: NA | J39: NA
A40: GSM1598446 | B40: CCFA_Risk_039 | C40: Ileum（回肠） | D40: 女 | E40: 15.33 | F40: A1b | G40: Not IBD | H40: Not IBD | I40: NA | J40: NA
...

Sheet RISK队列基线数据特征
B1: CD n=1098 | C1: Ctl n=380 | D1: UC n=178
A2: Mean (SD) Age (years) | B2: 12.2+/-3.1 | C2: 11.8+/-3.8 | D2: 12.2+/-3.4
A3: Male gender (%) | B3: 62 | C3: 74 | D3: 50
A4: Cau ethnicity (3 of 4 grandparents) (%) | B4: 75 | C4: 69 | D4: 75
A5: AA ethnicity (3 of 4 grandparents) (%) | B5: 8 | C5: 9 | D5: 5
A6: Other ethnicity (%) | B6: 17 | C6: 22 | D6: 20
A7: Perianal involvement (%) | B7: 15 | C7: na | D7: na
A8: Ileal deep ulcers (n=823) (%) | B8: 32 | C8: na | D8: na
A9: PCDAI Dx
A10: <=10 (inactive, %) | B10: 12 | C10: na | D10: na
A11: 11 to 30 (mild, %) | B11: 43 | C11: na | D11: na
A12: >=31 (moderate-severe, %) | B12: 45 | C12: na | D12: na

Sheet RISK回末数据统计特征
A1: IBD疾病类型 | E1: IBD疾病细分类型
A2: 分组 | B2: 样本数 | C2: 占比 | E2: 分组 | F2: 样本数 | G2: 占比
A3: CD | B3: =COUNTIF(RISK进展队列GEO回末测序数据整理!$G$2:$G$323,A3) -> 218 | C3: =B3/$B$6 -> 0.67701863 | E3: iCD | F3: =COUNTIF(RISK进展队列GEO回末测序数据整理!$H$2:$H$323,E3) -> 163 | G3: =F3/$F$7 -> 0.50621118
A4: UC | B4: =COUNTIF(RISK进展队列GEO回末测序数据整理!$G$2:$G$323,A4) -> 62 | C4: =B4/$B$6 -> 0.19254658 | E4: cCD | F4: =COUNTIF(RISK进展队列GEO回末测序数据整理!$H$2:$H$323,E4) -> 55 | G4: =F4/$F$7 -> 0.17080745
A5: Not IBD | B5: =COUNTIF(RISK进展队列GEO回末测序数据整理!$G$2:$G$323,A5) -> 42 | C5: =B5/$B$6 -> 0.13043478 | E5: UC | F5: =COUNTIF(RISK进展队列GEO回末测序数据整理!$H$2:$H$323,E5) -> 62 | G5: =F5/$F$7 -> 0.19254658
A6: 合计 | B6: =SUM(B3:B5) -> 322 | C6: =SUM(C3:C5) -> 1 | E6: Not IBD | F6: =COUNTIF(RISK进展队列GEO回末测序数据整理!$H$2:$H$323,E6) -> 42 | G6: =F6/$F$7 -> 0.13043478
E7: 合计 | F7: =SUM(F3:F6) -> 322 | G7: =SUM(G3:G6) -> 1
A9: 组织病理学特征 | E9: 深部溃疡
A10: 分组 | B10: 样本数 | C10: 占比 | E10: 分组 | F10: 样本数 | G10: 占比
A11: Macroscopic inflammation | B11: =COUNTIF(RISK进展队列GEO回末测序数据整理!$I$2:$I$323,A11) -> 162 | C11: =B11/$B$16 -> 0.50310559 | E11: Yes（1） | F11: =COUNTIF(RISK进展队列GEO回末测序数据整理!$J$2:$J$323,1) -> 76 | G11: =F11/$F$14 -> 0.23602484
A12: Microscopic inflammation | B12: =COUNTIF(RISK进展队列GEO回末测序数据整理!$I$2:$I$323,A12) -> 29 | C12: =B12/$B$16 -> 0.090062112 | E12: No（0） | F12: =COUNTIF(RISK进展队列GEO回末测序数据整理!$J$2:$J$323,0) -> 142 | G12: =F12/$F$14 -> 0.44099379
A13: Normal | B13: =COUNTIF(RISK进展队列GEO回末测序数据整理!$I$2:$I$323,A13) -> 24 | C13: =B13/$B$16 -> 0.074534161 | E13: NA | F13: =COUNTIF(RISK进展队列GEO回末测序数据整理!$J$2:$J$323,"NA") -> 104 | G13: =F13/$F$14 -> 0.32298137
A14: Undetermined | B14: =COUNTIF(RISK进展队列GEO回末测序数据整理!$I$2:$I$323,A14) -> 3 | C14: =B14/$B$16 -> 0.0093167702 | E14: 合计 | F14: =SUM(F11:F13) -> 322 | G14: =SUM(G11:G13) -> 1
A15: NA | B15: =COUNTIF(RISK进展队列GEO回末测序数据整理!$I$2:$I$323,A15) -> 104 | C15: =B15/$B$16 -> 0.32298137
A16: 合计 | B16: =SUM(B11:B15) -> 322 | C16: =SUM(C11:C15) -> 1
A18: 统计说明
A19: 统计范围：第二张工作表第2–323行，共322个GSM样本；四列均无空白。
A20: GEO中GSM1598427的diagnosis与l2 type原值为“not IBD”；COUNTIF不区分大小写，统计时与“Not IBD”合并。
A21: 深部溃疡按照“表注”转换并统计：Yes=1，No=0，NA保留为NA。
A22: 第二轮校对：逐GSM对照GEO family SOFT与series matrix，322个样本均一致，错配0。

Sheet RISK队列相关统计数据
A1: RISK队列相关统计数据 | P1: 公式辅助区（请勿修改；用于患者去重与口径标准化）
A2: 统计口径：所有结果单元格均保留Excel公式；患者级指标按患者编号去重。疾病字段统一Not IBD大小写，性别、病理和深部溃疡在辅助区标准化。NA不进入已知结局分母。 | P2: GSM编号 | Q2: 患者编号 | R2: 标准疾病组 | S2: CD亚型 | T2: 标准性别 | U2: 年龄 | V2: Paris分型 | W2: 标准病理 | X2: 深部溃疡 | Y2: 首次患者 | Z2: 首次患者-疾病组
P3: =RISK进展队列GEO回末测序数据整理!A2 -> GSM1598408 | Q3: =RISK进展队列GEO回末测序数据整理!B2 -> CCFA_Risk_001 | R3: =IF(LOWER(TRIM(RISK进展队列GEO回末测序数据整理!G2))="not ibd","Not IBD",TRIM(RISK进展队列GEO回末测序数据整理!G2)) -> CD | S3: =IF(LOWER(TRIM(RISK进展队列GEO回末测序数据整理!H2))="not ibd","Not IBD",TRIM(RISK进展队列GEO回末测序数据整理!H2)) -> iCD | T3: =IF(RISK进展队列GEO回末测序数据整理!D2="女","女性",IF(RISK进展队列GEO回末测序数据整理!D2="男","男性",TRIM(RISK进展队列GEO回末测序数据整理!D2))) -> 女性 | U3: =RISK进展队列GEO回末测序数据整理!E2 -> 15.25 | V3: =RISK进展队列GEO回末测序数据整理!F2 -> A1b | W3: =IF(RISK进展队列GEO回末测序数据整理!I2="Macroscopic inflammation","Macro",IF(RISK进展队列GEO回末测序数据整理!I2="Microscopic inflammation","Micro",TRIM(RISK进展队列GEO回末测序数据整理!I2))) -> Macro | X3: =IF(RISK进展队列GEO回末测序数据整理!J2=1,"Yes",IF(RISK进展队列GEO回末测序数据整理!J2=0,"No","N/A")) -> No | Y3: =IF(Q3="","",IF(COUNTIF($Q$3:Q3,Q3)=1,1,0)) -> 1 | Z3: =IF(Q3="","",IF(COUNTIFS($Q$3:Q3,Q3,$R$3:R3,R3)=1,1,0)) -> 1
A4: 1. 队列概览 | P4: =RISK进展队列GEO回末测序数据整理!A3 -> GSM1598409 | Q4: =RISK进展队列GEO回末测序数据整理!B3 -> CCFA_Risk_002 | R4: =IF(LOWER(TRIM(RISK进展队列GEO回末测序数据整理!G3))="not ibd","Not IBD",TRIM(RISK进展队列GEO回末测序数据整理!G3)) -> CD | S4: =IF(LOWER(TRIM(RISK进展队列GEO回末测序数据整理!H3))="not ibd","Not IBD",TRIM(RISK进展队列GEO回末测序数据整理!H3)) -> iCD | T4: =IF(RISK进展队列GEO回末测序数据整理!D3="女","女性",IF(RISK进展队列GEO回末测序数据整理!D3="男","男性",TRIM(RISK进展队列GEO回末测序数据整理!D3))) -> 男性 | U4: =RISK进展队列GEO回末测序数据整理!E3 -> 14.42 | V4: =RISK进展队列GEO回末测序数据整理!F3 -> A1b | W4: =IF(RISK进展队列GEO回末测序数据整理!I3="Macroscopic inflammation","Macro",IF(RISK进展队列GEO回末测序数据整理!I3="Microscopic inflammation","Micro",TRIM(RISK进展队列GEO回末测序数据整理!I3))) -> Macro | X4: =IF(RISK进展队列GEO回末测序数据整理!J3=1,"Yes",IF(RISK进展队列GEO回末测序数据整理!J3=0,"No","N/A")) -> No | Y4: =IF(Q4="","",IF(COUNTIF($Q$3:Q4,Q4)=1,1,0)) -> 1 | Z4: =IF(Q4="","",IF(COUNTIFS($Q$3:Q4,Q4,$R$3:R4,R4)=1,1,0)) -> 1
A5: 指标 | B5: 数值 | C5: 单位/分母 | D5: 说明 | P5: =RISK进展队列GEO回末测序数据整理!A4 -> GSM1598410 | Q5: =RISK进展队列GEO回末测序数据整理!B4 -> CCFA_Risk_003 | R5: =IF(LOWER(TRIM(RISK进展队列GEO回末测序数据整理!G4))="not ibd","Not IBD",TRIM(RISK进展队列GEO回末测序数据整理!G4)) -> CD | S5: =IF(LOWER(TRIM(RISK进展队列GEO回末测序数据整理!H4))="not ibd","Not IBD",TRIM(RISK进展队列GEO回末测序数据整理!H4)) -> iCD | T5: =IF(RISK进展队列GEO回末测序数据整理!D4="女","女性",IF(RISK进展队列GEO回末测序数据整理!D4="男","男性",TRIM(RISK进展队列GEO回末测序数据整理!D4))) -> 女性 | U5: =RISK进展队列GEO回末测序数据整理!E4 -> 12.5 | V5: =RISK进展队列GEO回末测序数据整理!F4 -> A1b | W5: =IF(RISK进展队列GEO回末测序数据整理!I4="Macroscopic inflammation","Macro",IF(RISK进展队列GEO回末测序数据整理!I4="Microscopic inflammation","Micro",TRIM(RISK进展队列GEO回末测序数据整理!I4))) -> Macro | X5: =IF(RISK进展队列GEO回末测序数据整理!J4=1,"Yes",IF(RISK进展队列GEO回末测序数据整理!J4=0,"No","N/A")) -> No | Y5: =IF(Q5="","",IF(COUNTIF($Q$3:Q5,Q5)=1,1,0)) -> 1 | Z5: =IF(Q5="","",IF(COUNTIFS($Q$3:Q5,Q5,$R$3:R5,R5)=1,1,0)) -> 1
A6: 样本数 | B6: =COUNTA($P$3:$P$324) -> 322 | C6: 份 | D6: GEO样本（GSM） | P6: =RISK进展队列GEO回末测序数据整理!A5 -> GSM1598411 | Q6: =RISK进展队列GEO回末测序数据整理!B5 -> CCFA_Risk_004 | R6: =IF(LOWER(TRIM(RISK进展队列GEO回末测序数据整理!G5))="not ibd","Not IBD",TRIM(RISK进展队列GEO回末测序数据整理!G5)) -> CD | S6: =IF(LOWER(TRIM(RISK进展队列GEO回末测序数据整理!H5))="not ibd","Not IBD",TRIM(RISK进展队列GEO回末测序数据整理!H5)) -> iCD | T6: =IF(RISK进展队列GEO回末测序数据整理!D5="女","女性",IF(RISK进展队列GEO回末测序数据整理!D5="男","男性",TRIM(RISK进展队列GEO回末测序数据整理!D5))) -> 男性 | U6: =RISK进展队列GEO回末测序数据整理!E5 -> 14.58 | V6: =RISK进展队列GEO回末测序数据整理!F5 -> A1b | W6: =IF(RISK进展队列GEO回末测序数据整理!I5="Macroscopic inflammation","Macro",IF(RISK进展队列GEO回末测序数据整理!I5="Microscopic inflammation","Micro",TRIM(RISK进展队列GEO回末测序数据整理!I5))) -> Macro | X6: =IF(RISK进展队列GEO回末测序数据整理!J5=1,"Yes",IF(RISK进展队列GEO回末测序数据整理!J5=0,"No","N/A")) -> No | Y6: =IF(Q6="","",IF(COUNTIF($Q$3:Q6,Q6)=1,1,0)) -> 1 | Z6: =IF(Q6="","",IF(COUNTIFS($Q$3:Q6,Q6,$R$3:R6,R6)=1,1,0)) -> 1
A7: 唯一患者数 | B7: =SUM($Y$3:$Y$324) -> 322 | C7: 人 | D7: 按患者编号去重 | P7: =RISK进展队列GEO回末测序数据整理!A6 -> GSM1598412 | Q7: =RISK进展队列GEO回末测序数据整理!B6 -> CCFA_Risk_005 | R7: =IF(LOWER(TRIM(RISK进展队列GEO回末测序数据整理!G6))="not ibd","Not IBD",TRIM(RISK进展队列GEO回末测序数据整理!G6)) -> CD | S7: =IF(LOWER(TRIM(RISK进展队列GEO回末测序数据整理!H6))="not ibd","Not IBD",TRIM(RISK进展队列GEO回末测序数据整理!H6)) -> iCD | T7: =IF(RISK进展队列GEO回末测序数据整理!D6="女","女性",IF(RISK进展队列GEO回末测序数据整理!D6="男","男性",TRIM(RISK进展队列GEO回末测序数据整理!D6))) -> 女性 | U7: =RISK进展队列GEO回末测序数据整理!E6 -> 10.17 | V7: =RISK进展队列GEO回末测序数据整理!F6 -> A1b | W7: =IF(RISK进展队列GEO回末测序数据整理!I6="Macroscopic inflammation","Macro",IF(RISK进展队列GEO回末测序数据整理!I6="Microscopic inflammation","Micro",TRIM(RISK进展队列GEO回末测序数据整理!I6))) -> Macro | X7: =IF(RISK进展队列GEO回末测序数据整理!J6=1,"Yes",IF(RISK进展队列GEO回末测序数据整理!J6=0,"No","N/A")) -> No | Y7: =IF(Q7="","",IF(COUNTIF($Q$3:Q7,Q7)=1,1,0)) -> 1 | Z7: =IF(Q7="","",IF(COUNTIFS($Q$3:Q7,Q7,$R$3:R7,R7)=1,1,0)) -> 1
A8: 平均样本数/患者 | B8: =IFERROR(B6/B7,"") -> 1 | C8: 份/人 | D8: 用于识别重复取样 | P8: =RISK进展队列GEO回末测序数据整理!A7 -> GSM1598413 | Q8: =RISK进展队列GEO回末测序数据整理!B7 -> CCFA_Risk_006 | R8: =IF(LOWER(TRIM(RISK进展队列GEO回末测序数据整理!G7))="not ibd","Not IBD",TRIM(RISK进展队列GEO回末测序数据整理!G7)) -> CD | S8: =IF(LOWER(TRIM(RISK进展队列GEO回末测序数据整理!H7))="not ibd","Not IBD",TRIM(RISK进展队列GEO回末测序数据整理!H7)) -> iCD | T8: =IF(RISK进展队列GEO回末测序数据整理!D7="女","女性",IF(RISK进展队列GEO回末测序数据整理!D7="男","男性",TRIM(RISK进展队列GEO回末测序数据整理!D7))) -> 女性 | U8: =RISK进展队列GEO回末测序数据整理!E7 -> 15.75 | V8: =RISK进展队列GEO回末测序数据整理!F7 -> A1b | W8: =IF(RISK进展队列GEO回末测序数据整理!I7="Macroscopic inflammation","Macro",IF(RISK进展队列GEO回末测序数据整理!I7="Microscopic inflammation","Micro",TRIM(RISK进展队列GEO回末测序数据整理!I7))) -> Macro | X8: =IF(RISK进展队列GEO回末测序数据整理!J7=1,"Yes",IF(RISK进展队列GEO回末测序数据整理!J7=0,"No","N/A")) -> Yes | Y8: =IF(Q8="","",IF(COUNTIF($Q$3:Q8,Q8)=1,1,0)) -> 1 | Z8: =IF(Q8="","",IF(COUNTIFS($Q$3:Q8,Q8,$R$3:R8,R8)=1,1,0)) -> 1
P9: =RISK进展队列GEO回末测序数据整理!A8 -> GSM1598414 | Q9: =RISK进展队列GEO回末测序数据整理!B8 -> CCFA_Risk_007 | R9: =IF(LOWER(TRIM(RISK进展队列GEO回末测序数据整理!G8))="not ibd","Not IBD",TRIM(RISK进展队列GEO回末测序数据整理!G8)) -> CD | S9: =IF(LOWER(TRIM(RISK进展队列GEO回末测序数据整理!H8))="not ibd","Not IBD",TRIM(RISK进展队列GEO回末测序数据整理!H8)) -> iCD | T9: =IF(RISK进展队列GEO回末测序数据整理!D8="女","女性",IF(RISK进展队列GEO回末测序数据整理!D8="男","男性",TRIM(RISK进展队列GEO回末测序数据整理!D8))) -> 男性 | U9: =RISK进展队列GEO回末测序数据整理!E8 -> 14.33 | V9: =RISK进展队列GEO回末测序数据整理!F8 -> A1b | W9: =IF(RISK进展队列GEO回末测序数据整理!I8="Macroscopic inflammation","Macro",IF(RISK进展队列GEO回末测序数据整理!I8="Microscopic inflammation","Micro",TRIM(RISK进展队列GEO回末测序数据整理!I8))) -> Macro | X9: =IF(RISK进展队列GEO回末测序数据整理!J8=1,"Yes",IF(RISK进展队列GEO回末测序数据整理!J8=0,"No","N/A")) -> No | Y9: =IF(Q9="","",IF(COUNTIF($Q$3:Q9,Q9)=1,1,0)) -> 1 | Z9: =IF(Q9="","",IF(COUNTIFS($Q$3:Q9,Q9,$R$3:R9,R9)=1,1,0)) -> 1
A10: 2. 疾病构成（患者级） | P10: =RISK进展队列GEO回末测序数据整理!A9 -> GSM1598415 | Q10: =RISK进展队列GEO回末测序数据整理!B9 -> CCFA_Risk_008 | R10: =IF(LOWER(TRIM(RISK进展队列GEO回末测序数据整理!G9))="not ibd","Not IBD",TRIM(RISK进展队列GEO回末测序数据整理!G9)) -> CD | S10: =IF(LOWER(TRIM(RISK进展队列GEO回末测序数据整理!H9))="not ibd","Not IBD",TRIM(RISK进展队列GEO回末测序数据整理!H9)) -> cCD | T10: =IF(RISK进展队列GEO回末测序数据整理!D9="女","女性",IF(RISK进展队列GEO回末测序数据整理!D9="男","男性",TRIM(RISK进展队列GEO回末测序数据整理!D9))) -> 男性 | U10: =RISK进展队列GEO回末测序数据整理!E9 -> 11.42 | V10: =RISK进展队列GEO回末测序数据整理!F9 -> A1b | W10: =IF(RISK进展队列GEO回末测序数据整理!I9="Macroscopic inflammation","Macro",IF(RISK进展队列GEO回末测序数据整理!I9="Microscopic inflammation","Micro",TRIM(RISK进展队列GEO回末测序数据整理!I9))) -> Normal | X10: =IF(RISK进展队列GEO回末测序数据整理!J9=1,"Yes",IF(RISK进展队列GEO回末测序数据整理!J9=0,"No","N/A")) -> No | Y10: =IF(Q10="","",IF(COUNTIF($Q$3:Q10,Q10)=1,1,0)) -> 1 | Z10: =IF(Q10="","",IF(COUNTIFS($Q$3:Q10,Q10,$R$3:R10,R10)=1,1,0)) -> 1
A11: 疾病组 | B11: 患者数 | C11: 患者占比 | D11: 统计口径 | P11: =RISK进展队列GEO回末测序数据整理!A10 -> GSM1598416 | Q11: =RISK进展队列GEO回末测序数据整理!B10 -> CCFA_Risk_009 | R11: =IF(LOWER(TRIM(RISK进展队列GEO回末测序数据整理!G10))="not ibd","Not IBD",TRIM(RISK进展队列GEO回末测序数据整理!G10)) -> CD | S11: =IF(LOWER(TRIM(RISK进展队列GEO回末测序数据整理!H10))="not ibd","Not IBD",TRIM(RISK进展队列GEO回末测序数据整理!H10)) -> iCD | T11: =IF(RISK进展队列GEO回末测序数据整理!D10="女","女性",IF(RISK进展队列GEO回末测序数据整理!D10="男","男性",TRIM(RISK进展队列GEO回末测序数据整理!D10))) -> 女性 | U11: =RISK进展队列GEO回末测序数据整理!E10 -> 9 | V11: =RISK进展队列GEO回末测序数据整理!F10 -> A1a | W11: =IF(RISK进展队列GEO回末测序数据整理!I10="Macroscopic inflammation","Macro",IF(RISK进展队列GEO回末测序数据整理!I10="Microscopic inflammation","Micro",TRIM(RISK进展队列GEO回末测序数据整理!I10))) -> Macro | X11: =IF(RISK进展队列GEO回末测序数据整理!J10=1,"Yes",IF(RISK进展队列GEO回末测序数据整理!J10=0,"No","N/A")) -> No | Y11: =IF(Q11="","",IF(COUNTIF($Q$3:Q11,Q11)=1,1,0)) -> 1 | Z11: =IF(Q11="","",IF(COUNTIFS($Q$3:Q11,Q11,$R$3:R11,R11)=1,1,0)) -> 1
A12: CD | B12: =SUMIFS($Z$3:$Z$324,$R$3:$R$324,A12) -> 218 | C12: =IFERROR(B12/$B$15,"") -> 0.67701863 | D12: 按患者-疾病组首次出现计数 | P12: =RISK进展队列GEO回末测序数据整理!A11 -> GSM1598417 | Q12: =RISK进展队列GEO回末测序数据整理!B11 -> CCFA_Risk_010 | R12: =IF(LOWER(TRIM(RISK进展队列GEO回末测序数据整理!G11))="not ibd","Not IBD",TRIM(RISK进展队列GEO回末测序数据整理!G11)) -> Not IBD | S12: =IF(LOWER(TRIM(RISK进展队列GEO回末测序数据整理!H11))="not ibd","Not IBD",TRIM(RISK进展队列GEO回末测序数据整理!H11)) -> Not IBD | T12: =IF(RISK进展队列GEO回末测序数据整理!D11="女","女性",IF(RISK进展队列GEO回末测序数据整理!D11="男","男性",TRIM(RISK进展队列GEO回末测序数据整理!D11))) -> 男性 | U12: =RISK进展队列GEO回末测序数据整理!E11 -> 10.33 | V12: =RISK进展队列GEO回末测序数据整理!F11 -> A1b | W12: =IF(RISK进展队列GEO回末测序数据整理!I11="Macroscopic inflammation","Macro",IF(RISK进展队列GEO回末测序数据整理!I11="Microscopic inflammation","Micro",TRIM(RISK进展队列GEO回末测序数据整理!I11))) -> NA | X12: =IF(RISK进展队列GEO回末测序数据整理!J11=1,"Yes",IF(RISK进展队列GEO回末测序数据整理!J11=0,"No","N/A")) -> N/A | Y12: =IF(Q12="","",IF(COUNTIF($Q$3:Q12,Q12)=1,1,0)) -> 1 | Z12: =IF(Q12="","",IF(COUNTIFS($Q$3:Q12,Q12,$R$3:R12,R12)=1,1,0)) -> 1
A13: UC | B13: =SUMIFS($Z$3:$Z$324,$R$3:$R$324,A13) -> 62 | C13: =IFERROR(B13/$B$15,"") -> 0.19254658 | D13: 按患者-疾病组首次出现计数 | P13: =RISK进展队列GEO回末测序数据整理!A12 -> GSM1598418 | Q13: =RISK进展队列GEO回末测序数据整理!B12 -> CCFA_Risk_011 | R13: =IF(LOWER(TRIM(RISK进展队列GEO回末测序数据整理!G12))="not ibd","Not IBD",TRIM(RISK进展队列GEO回末测序数据整理!G12)) -> Not IBD | S13: =IF(LOWER(TRIM(RISK进展队列GEO回末测序数据整理!H12))="not ibd","Not IBD",TRIM(RISK进展队列GEO回末测序数据整理!H12)) -> Not IBD | T13: =IF(RISK进展队列GEO回末测序数据整理!D12="女","女性",IF(RISK进展队列GEO回末测序数据整理!D12="男","男性",TRIM(RISK进展队列GEO回末测序数据整理!D12))) -> 男性 | U13: =RISK进展队列GEO回末测序数据整理!E12 -> 10.83 | V13: =RISK进展队列GEO回末测序数据整理!F12 -> A1b | W13: =IF(RISK进展队列GEO回末测序数据整理!I12="Macroscopic inflammation","Macro",IF(RISK进展队列GEO回末测序数据整理!I12="Microscopic inflammation","Micro",TRIM(RISK进展队列GEO回末测序数据整理!I12))) -> NA | X13: =IF(RISK进展队列GEO回末测序数据整理!J12=1,"Yes",IF(RISK进展队列GEO回末测序数据整理!J12=0,"No","N/A")) -> N/A | Y13: =IF(Q13="","",IF(COUNTIF($Q$3:Q13,Q13)=1,1,0)) -> 1 | Z13: =IF(Q13="","",IF(COUNTIFS($Q$3:Q13,Q13,$R$3:R13,R13)=1,1,0)) -> 1
A14: Not IBD | B14: =SUMIFS($Z$3:$Z$324,$R$3:$R$324,A14) -> 42 | C14: =IFERROR(B14/$B$15,"") -> 0.13043478 | D14: 按患者-疾病组首次出现计数 | P14: =RISK进展队列GEO回末测序数据整理!A13 -> GSM1598419 | Q14: =RISK进展队列GEO回末测序数据整理!B13 -> CCFA_Risk_012 | R14: =IF(LOWER(TRIM(RISK进展队列GEO回末测序数据整理!G13))="not ibd","Not IBD",TRIM(RISK进展队列GEO回末测序数据整理!G13)) -> CD | S14: =IF(LOWER(TRIM(RISK进展队列GEO回末测序数据整理!H13))="not ibd","Not IBD",TRIM(RISK进展队列GEO回末测序数据整理!H13)) -> cCD | T14: =IF(RISK进展队列GEO回末测序数据整理!D13="女","女性",IF(RISK进展队列GEO回末测序数据整理!D13="男","男性",TRIM(RISK进展队列GEO回末测序数据整理!D13))) -> 女性 | U14: =RISK进展队列GEO回末测序数据整理!E13 -> 13.92 | V14: =RISK进展队列GEO回末测序数据整理!F13 -> A1b | W14: =IF(RISK进展队列GEO回末测序数据整理!I13="Macroscopic inflammation","Macro",IF(RISK进展队列GEO回末测序数据整理!I13="Microscopic inflammation","Micro",TRIM(RISK进展队列GEO回末测序数据整理!I13))) -> Micro | X14: =IF(RISK进展队列GEO回末测序数据整理!J13=1,"Yes",IF(RISK进展队列GEO回末测序数据整理!J13=0,"No","N/A")) -> No | Y14: =IF(Q14="","",IF(COUNTIF($Q$3:Q14,Q14)=1,1,0)) -> 1 | Z14: =IF(Q14="","",IF(COUNTIFS($Q$3:Q14,Q14,$R$3:R14,R14)=1,1,0)) -> 1
A15: 合计 | B15: =SUM(B12:B14) -> 322 | C15: =SUM(C12:C14) -> 1 | P15: =RISK进展队列GEO回末测序数据整理!A14 -> GSM1598420 | Q15: =RISK进展队列GEO回末测序数据整理!B14 -> CCFA_Risk_013 | R15: =IF(LOWER(TRIM(RISK进展队列GEO回末测序数据整理!G14))="not ibd","Not IBD",TRIM(RISK进展队列GEO回末测序数据整理!G14)) -> CD | S15: =IF(LOWER(TRIM(RISK进展队列GEO回末测序数据整理!H14))="not ibd","Not IBD",TRIM(RISK进展队列GEO回末测序数据整理!H14)) -> iCD | T15: =IF(RISK进展队列GEO回末测序数据整理!D14="女","女性",IF(RISK进展队列GEO回末测序数据整理!D14="男","男性",TRIM(RISK进展队列GEO回末测序数据整理!D14))) -> 男性 | U15: =RISK进展队列GEO回末测序数据整理!E14 -> 9.25 | V15: =RISK进展队列GEO回末测序数据整理!F14 -> A1a | W15: =IF(RISK进展队列GEO回末测序数据整理!I14="Macroscopic inflammation","Macro",IF(RISK进展队列GEO回末测序数据整理!I14="Microscopic inflammation","Micro",TRIM(RISK进展队列GEO回末测序数据整理!I14))) -> Macro | X15: =IF(RISK进展队列GEO回末测序数据整理!J14=1,"Yes",IF(RISK进展队列GEO回末测序数据整理!J14=0,"No","N/A")) -> No | Y15: =IF(Q15="","",IF(COUNTIF($Q$3:Q15,Q15)=1,1,0)) -> 1 | Z15: =IF(Q15="","",IF(COUNTIFS($Q$3:Q15,Q15,$R$3:R15,R15)=1,1,0)) -> 1
P16: =RISK进展队列GEO回末测序数据整理!A15 -> GSM1598421 | Q16: =RISK进展队列GEO回末测序数据整理!B15 -> CCFA_Risk_014 | R16: =IF(LOWER(TRIM(RISK进展队列GEO回末测序数据整理!G15))="not ibd","Not IBD",TRIM(RISK进展队列GEO回末测序数据整理!G15)) -> Not IBD | S16: =IF(LOWER(TRIM(RISK进展队列GEO回末测序数据整理!H15))="not ibd","Not IBD",TRIM(RISK进展队列GEO回末测序数据整理!H15)) -> Not IBD | T16: =IF(RISK进展队列GEO回末测序数据整理!D15="女","女性",IF(RISK进展队列GEO回末测序数据整理!D15="男","男性",TRIM(RISK进展队列GEO回末测序数据整理!D15))) -> 女性 | U16: =RISK进展队列GEO回末测序数据整理!E15 -> 9 | V16: =RISK进展队列GEO回末测序数据整理!F15 -> A1a | W16: =IF(RISK进展队列GEO回末测序数据整理!I15="Macroscopic inflammation","Macro",IF(RISK进展队列GEO回末测序数据整理!I15="Microscopic inflammation","Micro",TRIM(RISK进展队列GEO回末测序数据整理!I15))) -> NA | X16: =IF(RISK进展队列GEO回末测序数据整理!J15=1,"Yes",IF(RISK进展队列GEO回末测序数据整理!J15=0,"No","N/A")) -> N/A | Y16: =IF(Q16="","",IF(COUNTIF($Q$3:Q16,Q16)=1,1,0)) -> 1 | Z16: =IF(Q16="","",IF(COUNTIFS($Q$3:Q16,Q16,$R$3:R16,R16)=1,1,0)) -> 1
A17: 3. 性别与年龄（全队列） | P17: =RISK进展队列GEO回末测序数据整理!A16 -> GSM1598422 | Q17: =RISK进展队列GEO回末测序数据整理!B16 -> CCFA_Risk_015 | R17: =IF(LOWER(TRIM(RISK进展队列GEO回末测序数据整理!G16))="not ibd","Not IBD",TRIM(RISK进展队列GEO回末测序数据整理!G16)) -> CD | S17: =IF(LOWER(TRIM(RISK进展队列GEO回末测序数据整理!H16))="not ibd","Not IBD",TRIM(RISK进展队列GEO回末测序数据整理!H16)) -> iCD | T17: =IF(RISK进展队列GEO回末测序数据整理!D16="女","女性",IF(RISK进展队列GEO回末测序数据整理!D16="男","男性",TRIM(RISK进展队列GEO回末测序数据整理!D16))) -> 男性 | U17: =RISK进展队列GEO回末测序数据整理!E16 -> 13.42 | V17: =RISK进展队列GEO回末测序数据整理!F16 -> A1b | W17: =IF(RISK进展队列GEO回末测序数据整理!I16="Macroscopic inflammation","Macro",IF(RISK进展队列GEO回末测序数据整理!I16="Microscopic inflammation","Micro",TRIM(RISK进展队列GEO回末测序数据整理!I16))) -> Macro | X17: =IF(RISK进展队列GEO回末测序数据整理!J16=1,"Yes",IF(RISK进展队列GEO回末测序数据整理!J16=0,"No","N/A")) -> No | Y17: =IF(Q17="","",IF(COUNTIF($Q$3:Q17,Q17)=1,1,0)) -> 1 | Z17: =IF(Q17="","",IF(COUNTIFS($Q$3:Q17,Q17,$R$3:R17,R17)=1,1,0)) -> 1
A18: 性别 | B18: 患者数 | C18: 患者占比 | D18: 说明 | P18: =RISK进展队列GEO回末测序数据整理!A17 -> GSM1598423 | Q18: =RISK进展队列GEO回末测序数据整理!B17 -> CCFA_Risk_016 | R18: =IF(LOWER(TRIM(RISK进展队列GEO回末测序数据整理!G17))="not ibd","Not IBD",TRIM(RISK进展队列GEO回末测序数据整理!G17)) -> CD | S18: =IF(LOWER(TRIM(RISK进展队列GEO回末测序数据整理!H17))="not ibd","Not IBD",TRIM(RISK进展队列GEO回末测序数据整理!H17)) -> iCD | T18: =IF(RISK进展队列GEO回末测序数据整理!D17="女","女性",IF(RISK进展队列GEO回末测序数据整理!D17="男","男性",TRIM(RISK进展队列GEO回末测序数据整理!D17))) -> 男性 | U18: =RISK进展队列GEO回末测序数据整理!E17 -> 15.17 | V18: =RISK进展队列GEO回末测序数据整理!F17 -> A1b | W18: =IF(RISK进展队列GEO回末测序数据整理!I17="Macroscopic inflammation","Macro",IF(RISK进展队列GEO回末测序数据整理!I17="Microscopic inflammation","Micro",TRIM(RISK进展队列GEO回末测序数据整理!I17))) -> Macro | X18: =IF(RISK进展队列GEO回末测序数据整理!J17=1,"Yes",IF(RISK进展队列GEO回末测序数据整理!J17=0,"No","N/A")) -> No | Y18: =IF(Q18="","",IF(COUNTIF($Q$3:Q18,Q18)=1,1,0)) -> 1 | Z18: =IF(Q18="","",IF(COUNTIFS($Q$3:Q18,Q18,$R$3:R18,R18)=1,1,0)) -> 1
A19: 女性 | B19: =SUMIFS($Y$3:$Y$324,$T$3:$T$324,A19) -> 135 | C19: =IFERROR(B19/$B$21,"") -> 0.41925466 | D19: 患者级 | P19: =RISK进展队列GEO回末测序数据整理!A18 -> GSM1598424 | Q19: =RISK进展队列GEO回末测序数据整理!B18 -> CCFA_Risk_017 | R19: =IF(LOWER(TRIM(RISK进展队列GEO回末测序数据整理!G18))="not ibd","Not IBD",TRIM(RISK进展队列GEO回末测序数据整理!G18)) -> CD | S19: =IF(LOWER(TRIM(RISK进展队列GEO回末测序数据整理!H18))="not ibd","Not IBD",TRIM(RISK进展队列GEO回末测序数据整理!H18)) -> iCD | T19: =IF(RISK进展队列GEO回末测序数据整理!D18="女","女性",IF(RISK进展队列GEO回末测序数据整理!D18="男","男性",TRIM(RISK进展队列GEO回末测序数据整理!D18))) -> 男性 | U19: =RISK进展队列GEO回末测序数据整理!E18 -> 13.25 | V19: =RISK进展队列GEO回末测序数据整理!F18 -> A1b | W19: =IF(RISK进展队列GEO回末测序数据整理!I18="Macroscopic inflammation","Macro",IF(RISK进展队列GEO回末测序数据整理!I18="Microscopic inflammation","Micro",TRIM(RISK进展队列GEO回末测序数据整理!I18))) -> Macro | X19: =IF(RISK进展队列GEO回末测序数据整理!J18=1,"Yes",IF(RISK进展队列GEO回末测序数据整理!J18=0,"No","N/A")) -> Yes | Y19: =IF(Q19="","",IF(COUNTIF($Q$3:Q19,Q19)=1,1,0)) -> 1 | Z19: =IF(Q19="","",IF(COUNTIFS($Q$3:Q19,Q19,$R$3:R19,R19)=1,1,0)) -> 1
A20: 男性 | B20: =SUMIFS($Y$3:$Y$324,$T$3:$T$324,A20) -> 187 | C20: =IFERROR(B20/$B$21,"") -> 0.58074534 | D20: 患者级 | P20: =RISK进展队列GEO回末测序数据整理!A19 -> GSM1598425 | Q20: =RISK进展队列GEO回末测序数据整理!B19 -> CCFA_Risk_018 | R20: =IF(LOWER(TRIM(RISK进展队列GEO回末测序数据整理!G19))="not ibd","Not IBD",TRIM(RISK进展队列GEO回末测序数据整理!G19)) -> CD | S20: =IF(LOWER(TRIM(RISK进展队列GEO回末测序数据整理!H19))="not ibd","Not IBD",TRIM(RISK进展队列GEO回末测序数据整理!H19)) -> iCD | T20: =IF(RISK进展队列GEO回末测序数据整理!D19="女","女性",IF(RISK进展队列GEO回末测序数据整理!D19="男","男性",TRIM(RISK进展队列GEO回末测序数据整理!D19))) -> 女性 | U20: =RISK进展队列GEO回末测序数据整理!E19 -> 16.08 | V20: =RISK进展队列GEO回末测序数据整理!F19 -> A1b | W20: =IF(RISK进展队列GEO回末测序数据整理!I19="Macroscopic inflammation","Macro",IF(RISK进展队列GEO回末测序数据整理!I19="Microscopic inflammation","Micro",TRIM(RISK进展队列GEO回末测序数据整理!I19))) -> Macro | X20: =IF(RISK进展队列GEO回末测序数据整理!J19=1,"Yes",IF(RISK进展队列GEO回末测序数据整理!J19=0,"No","N/A")) -> No | Y20: =IF(Q20="","",IF(COUNTIF($Q$3:Q20,Q20)=1,1,0)) -> 1 | Z20: =IF(Q20="","",IF(COUNTIFS($Q$3:Q20,Q20,$R$3:R20,R20)=1,1,0)) -> 1
A21: 合计 | B21: =SUM(B19:B20) -> 322 | C21: =SUM(C19:C20) -> 1 | P21: =RISK进展队列GEO回末测序数据整理!A20 -> GSM1598426 | Q21: =RISK进展队列GEO回末测序数据整理!B20 -> CCFA_Risk_019 | R21: =IF(LOWER(TRIM(RISK进展队列GEO回末测序数据整理!G20))="not ibd","Not IBD",TRIM(RISK进展队列GEO回末测序数据整理!G20)) -> Not IBD | S21: =IF(LOWER(TRIM(RISK进展队列GEO回末测序数据整理!H20))="not ibd","Not IBD",TRIM(RISK进展队列GEO回末测序数据整理!H20)) -> Not IBD | T21: =IF(RISK进展队列GEO回末测序数据整理!D20="女","女性",IF(RISK进展队列GEO回末测序数据整理!D20="男","男性",TRIM(RISK进展队列GEO回末测序数据整理!D20))) -> 女性 | U21: =RISK进展队列GEO回末测序数据整理!E20 -> 15 | V21: =RISK进展队列GEO回末测序数据整理!F20 -> A1b | W21: =IF(RISK进展队列GEO回末测序数据整理!I20="Macroscopic inflammation","Macro",IF(RISK进展队列GEO回末测序数据整理!I20="Microscopic inflammation","Micro",TRIM(RISK进展队列GEO回末测序数据整理!I20))) -> NA | X21: =IF(RISK进展队列GEO回末测序数据整理!J20=1,"Yes",IF(RISK进展队列GEO回末测序数据整理!J20=0,"No","N/A")) -> N/A | Y21: =IF(Q21="","",IF(COUNTIF($Q$3:Q21,Q21)=1,1,0)) -> 1 | Z21: =IF(Q21="","",IF(COUNTIFS($Q$3:Q21,Q21,$R$3:R21,R21)=1,1,0)) -> 1
P22: =RISK进展队列GEO回末测序数据整理!A21 -> GSM1598427 | Q22: =RISK进展队列GEO回末测序数据整理!B21 -> CCFA_Risk_020 | R22: =IF(LOWER(TRIM(RISK进展队列GEO回末测序数据整理!G21))="not ibd","Not IBD",TRIM(RISK进展队列GEO回末测序数据整理!G21)) -> Not IBD | S22: =IF(LOWER(TRIM(RISK进展队列GEO回末测序数据整理!H21))="not ibd","Not IBD",TRIM(RISK进展队列GEO回末测序数据整理!H21)) -> Not IBD | T22: =IF(RISK进展队列GEO回末测序数据整理!D21="女","女性",IF(RISK进展队列GEO回末测序数据整理!D21="男","男性",TRIM(RISK进展队列GEO回末测序数据整理!D21))) -> 女性 | U22: =RISK进展队列GEO回末测序数据整理!E21 -> 10.75 | V22: =RISK进展队列GEO回末测序数据整理!F21 -> A1b | W22: =IF(RISK进展队列GEO回末测序数据整理!I21="Macroscopic inflammation","Macro",IF(RISK进展队列GEO回末测序数据整理!I21="Microscopic inflammation","Micro",TRIM(RISK进展队列GEO回末测序数据整理!I21))) -> NA | X22: =IF(RISK进展队列GEO回末测序数据整理!J21=1,"Yes",IF(RISK进展队列GEO回末测序数据整理!J21=0,"No","N/A")) -> N/A | Y22: =IF(Q22="","",IF(COUNTIF($Q$3:Q22,Q22)=1,1,0)) -> 1 | Z22: =IF(Q22="","",IF(COUNTIFS($Q$3:Q22,Q22,$R$3:R22,R22)=1,1,0)) -> 1
A23: 年龄指标 | B23: 数值 | C23: 单位 | D23: 说明 | P23: =RISK进展队列GEO回末测序数据整理!A22 -> GSM1598428 | Q23: =RISK进展队列GEO回末测序数据整理!B22 -> CCFA_Risk_021 | R23: =IF(LOWER(TRIM(RISK进展队列GEO回末测序数据整理!G22))="not ibd","Not IBD",TRIM(RISK进展队列GEO回末测序数据整理!G22)) -> CD | S23: =IF(LOWER(TRIM(RISK进展队列GEO回末测序数据整理!H22))="not ibd","Not IBD",TRIM(RISK进展队列GEO回末测序数据整理!H22)) -> iCD | T23: =IF(RISK进展队列GEO回末测序数据整理!D22="女","女性",IF(RISK进展队列GEO回末测序数据整理!D22="男","男性",TRIM(RISK进展队列GEO回末测序数据整理!D22))) -> 男性 | U23: =RISK进展队列GEO回末测序数据整理!E22 -> 10.33 | V23: =RISK进展队列GEO回末测序数据整理!F22 -> A1b | W23: =IF(RISK进展队列GEO回末测序数据整理!I22="Macroscopic inflammation","Macro",IF(RISK进展队列GEO回末测序数据整理!I22="Microscopic inflammation","Micro",TRIM(RISK进展队列GEO回末测序数据整理!I22))) -> Macro | X23: =IF(RISK进展队列GEO回末测序数据整理!J22=1,"Yes",IF(RISK进展队列GEO回末测序数据整理!J22=0,"No","N/A")) -> Yes | Y23: =IF(Q23="","",IF(COUNTIF($Q$3:Q23,Q23)=1,1,0)) -> 1 | Z23: =IF(Q23="","",IF(COUNTIFS($Q$3:Q23,Q23,$R$3:R23,R23)=1,1,0)) -> 1
A24: 均值 | B24: =AVERAGE($U$3:$U$324) -> 11.938323 | C24: 岁 | D24: 诊断/入组年龄 | P24: =RISK进展队列GEO回末测序数据整理!A23 -> GSM1598429 | Q24: =RISK进展队列GEO回末测序数据整理!B23 -> CCFA_Risk_022 | R24: =IF(LOWER(TRIM(RISK进展队列GEO回末测序数据整理!G23))="not ibd","Not IBD",TRIM(RISK进展队列GEO回末测序数据整理!G23)) -> CD | S24: =IF(LOWER(TRIM(RISK进展队列GEO回末测序数据整理!H23))="not ibd","Not IBD",TRIM(RISK进展队列GEO回末测序数据整理!H23)) -> iCD | T24: =IF(RISK进展队列GEO回末测序数据整理!D23="女","女性",IF(RISK进展队列GEO回末测序数据整理!D23="男","男性",TRIM(RISK进展队列GEO回末测序数据整理!D23))) -> 女性 | U24: =RISK进展队列GEO回末测序数据整理!E23 -> 10.83 | V24: =RISK进展队列GEO回末测序数据整理!F23 -> A1b | W24: =IF(RISK进展队列GEO回末测序数据整理!I23="Macroscopic inflammation","Macro",IF(RISK进展队列GEO回末测序数据整理!I23="Microscopic inflammation","Micro",TRIM(RISK进展队列GEO回末测序数据整理!I23))) -> Macro | X24: =IF(RISK进展队列GEO回末测序数据整理!J23=1,"Yes",IF(RISK进展队列GEO回末测序数据整理!J23=0,"No","N/A")) -> Yes | Y24: =IF(Q24="","",IF(COUNTIF($Q$3:Q24,Q24)=1,1,0)) -> 1 | Z24: =IF(Q24="","",IF(COUNTIFS($Q$3:Q24,Q24,$R$3:R24,R24)=1,1,0)) -> 1
A25: 标准差 | B25: =STDEV($U$3:$U$324) -> 3.1710107 | C25: 岁 | D25: 诊断/入组年龄 | P25: =RISK进展队列GEO回末测序数据整理!A24 -> GSM1598430 | Q25: =RISK进展队列GEO回末测序数据整理!B24 -> CCFA_Risk_023 | R25: =IF(LOWER(TRIM(RISK进展队列GEO回末测序数据整理!G24))="not ibd","Not IBD",TRIM(RISK进展队列GEO回末测序数据整理!G24)) -> CD | S25: =IF(LOWER(TRIM(RISK进展队列GEO回末测序数据整理!H24))="not ibd","Not IBD",TRIM(RISK进展队列GEO回末测序数据整理!H24)) -> iCD | T25: =IF(RISK进展队列GEO回末测序数据整理!D24="女","女性",IF(RISK进展队列GEO回末测序数据整理!D24="男","男性",TRIM(RISK进展队列GEO回末测序数据整理!D24))) -> 女性 | U25: =RISK进展队列GEO回末测序数据整理!E24 -> 10.17 | V25: =RISK进展队列GEO回末测序数据整理!F24 -> A1b | W25: =IF(RISK进展队列GEO回末测序数据整理!I24="Macroscopic inflammation","Macro",IF(RISK进展队列GEO回末测序数据整理!I24="Microscopic inflammation","Micro",TRIM(RISK进展队列GEO回末测序数据整理!I24))) -> Macro | X25: =IF(RISK进展队列GEO回末测序数据整理!J24=1,"Yes",IF(RISK进展队列GEO回末测序数据整理!J24=0,"No","N/A")) -> Yes | Y25: =IF(Q25="","",IF(COUNTIF($Q$3:Q25,Q25)=1,1,0)) -> 1 | Z25: =IF(Q25="","",IF(COUNTIFS($Q$3:Q25,Q25,$R$3:R25,R25)=1,1,0)) -> 1
A26: 中位数 | B26: =MEDIAN($U$3:$U$324) -> 12 | C26: 岁 | D26: 诊断/入组年龄 | P26: =RISK进展队列GEO回末测序数据整理!A25 -> GSM1598431 | Q26: =RISK进展队列GEO回末测序数据整理!B25 -> CCFA_Risk_024 | R26: =IF(LOWER(TRIM(RISK进展队列GEO回末测序数据整理!G25))="not ibd","Not IBD",TRIM(RISK进展队列GEO回末测序数据整理!G25)) -> CD | S26: =IF(LOWER(TRIM(RISK进展队列GEO回末测序数据整理!H25))="not ibd","Not IBD",TRIM(RISK进展队列GEO回末测序数据整理!H25)) -> iCD | T26: =IF(RISK进展队列GEO回末测序数据整理!D25="女","女性",IF(RISK进展队列GEO回末测序数据整理!D25="男","男性",TRIM(RISK进展队列GEO回末测序数据整理!D25))) -> 男性 | U26: =RISK进展队列GEO回末测序数据整理!E25 -> 4.5 | V26: =RISK进展队列GEO回末测序数据整理!F25 -> A1a | W26: =IF(RISK进展队列GEO回末测序数据整理!I25="Macroscopic inflammation","Macro",IF(RISK进展队列GEO回末测序数据整理!I25="Microscopic inflammation","Micro",TRIM(RISK进展队列GEO回末测序数据整理!I25))) -> Macro | X26: =IF(RISK进展队列GEO回末测序数据整理!J25=1,"Yes",IF(RISK进展队列GEO回末测序数据整理!J25=0,"No","N/A")) -> No | Y26: =IF(Q26="","",IF(COUNTIF($Q$3:Q26,Q26)=1,1,0)) -> 1 | Z26: =IF(Q26="","",IF(COUNTIFS($Q$3:Q26,Q26,$R$3:R26,R26)=1,1,0)) -> 1
A27: 最小值 | B27: =MIN($U$3:$U$324) -> 2.25 | C27: 岁 | D27: 诊断/入组年龄 | P27: =RISK进展队列GEO回末测序数据整理!A26 -> GSM1598432 | Q27: =RISK进展队列GEO回末测序数据整理!B26 -> CCFA_Risk_025 | R27: =IF(LOWER(TRIM(RISK进展队列GEO回末测序数据整理!G26))="not ibd","Not IBD",TRIM(RISK进展队列GEO回末测序数据整理!G26)) -> CD | S27: =IF(LOWER(TRIM(RISK进展队列GEO回末测序数据整理!H26))="not ibd","Not IBD",TRIM(RISK进展队列GEO回末测序数据整理!H26)) -> iCD | T27: =IF(RISK进展队列GEO回末测序数据整理!D26="女","女性",IF(RISK进展队列GEO回末测序数据整理!D26="男","男性",TRIM(RISK进展队列GEO回末测序数据整理!D26))) -> 女性 | U27: =RISK进展队列GEO回末测序数据整理!E26 -> 6.33 | V27: =RISK进展队列GEO回末测序数据整理!F26 -> A1a | W27: =IF(RISK进展队列GEO回末测序数据整理!I26="Macroscopic inflammation","Macro",IF(RISK进展队列GEO回末测序数据整理!I26="Microscopic inflammation","Micro",TRIM(RISK进展队列GEO回末测序数据整理!I26))) -> Macro | X27: =IF(RISK进展队列GEO回末测序数据整理!J26=1,"Yes",IF(RISK进展队列GEO回末测序数据整理!J26=0,"No","N/A")) -> No | Y27: =IF(Q27="","",IF(COUNTIF($Q$3:Q27,Q27)=1,1,0)) -> 1 | Z27: =IF(Q27="","",IF(COUNTIFS($Q$3:Q27,Q27,$R$3:R27,R27)=1,1,0)) -> 1
A28: 最大值 | B28: =MAX($U$3:$U$324) -> 17.08 | C28: 岁 | D28: 诊断/入组年龄 | P28: =RISK进展队列GEO回末测序数据整理!A27 -> GSM1598433 | Q28: =RISK进展队列GEO回末测序数据整理!B27 -> CCFA_Risk_026 | R28: =IF(LOWER(TRIM(RISK进展队列GEO回末测序数据整理!G27))="not ibd","Not IBD",TRIM(RISK进展队列GEO回末测序数据整理!G27)) -> CD | S28: =IF(LOWER(TRIM(RISK进展队列GEO回末测序数据整理!H27))="not ibd","Not IBD",TRIM(RISK进展队列GEO回末测序数据整理!H27)) -> iCD | T28: =IF(RISK进展队列GEO回末测序数据整理!D27="女","女性",IF(RISK进展队列GEO回末测序数据整理!D27="男","男性",TRIM(RISK进展队列GEO回末测序数据整理!D27))) -> 男性 | U28: =RISK进展队列GEO回末测序数据整理!E27 -> 5.08 | V28: =RISK进展队列GEO回末测序数据整理!F27 -> A1a | W28: =IF(RISK进展队列GEO回末测序数据整理!I27="Macroscopic inflammation","Macro",IF(RISK进展队列GEO回末测序数据整理!I27="Microscopic inflammation","Micro",TRIM(RISK进展队列GEO回末测序数据整理!I27))) -> Macro | X28: =IF(RISK进展队列GEO回末测序数据整理!J27=1,"Yes",IF(RISK进展队列GEO回末测序数据整理!J27=0,"No","N/A")) -> No | Y28: =IF(Q28="","",IF(COUNTIF($Q$3:Q28,Q28)=1,1,0)) -> 1 | Z28: =IF(Q28="","",IF(COUNTIFS($Q$3:Q28,Q28,$R$3:R28,R28)=1,1,0)) -> 1
P29: =RISK进展队列GEO回末测序数据整理!A28 -> GSM1598434 | Q29: =RISK进展队列GEO回末测序数据整理!B28 -> CCFA_Risk_027 | R29: =IF(LOWER(TRIM(RISK进展队列GEO回末测序数据整理!G28))="not ibd","Not IBD",TRIM(RISK进展队列GEO回末测序数据整理!G28)) -> CD | S29: =IF(LOWER(TRIM(RISK进展队列GEO回末测序数据整理!H28))="not ibd","Not IBD",TRIM(RISK进展队列GEO回末测序数据整理!H28)) -> iCD | T29: =IF(RISK进展队列GEO回末测序数据整理!D28="女","女性",IF(RISK进展队列GEO回末测序数据整理!D28="男","男性",TRIM(RISK进展队列GEO回末测序数据整理!D28))) -> 女性 | U29: =RISK进展队列GEO回末测序数据整理!E28 -> 10.33 | V29: =RISK进展队列GEO回末测序数据整理!F28 -> A1b | W29: =IF(RISK进展队列GEO回末测序数据整理!I28="Macroscopic inflammation","Macro",IF(RISK进展队列GEO回末测序数据整理!I28="Microscopic inflammation","Micro",TRIM(RISK进展队列GEO回末测序数据整理!I28))) -> Macro | X29: =IF(RISK进展队列GEO回末测序数据整理!J28=1,"Yes",IF(RISK进展队列GEO回末测序数据整理!J28=0,"No","N/A")) -> Yes | Y29: =IF(Q29="","",IF(COUNTIF($Q$3:Q29,Q29)=1,1,0)) -> 1 | Z29: =IF(Q29="","",IF(COUNTIFS($Q$3:Q29,Q29,$R$3:R29,R29)=1,1,0)) -> 1
A30: 4. CD亚型构成（患者级） | P30: =RISK进展队列GEO回末测序数据整理!A29 -> GSM1598435 | Q30: =RISK进展队列GEO回末测序数据整理!B29 -> CCFA_Risk_028 | R30: =IF(LOWER(TRIM(RISK进展队列GEO回末测序数据整理!G29))="not ibd","Not IBD",TRIM(RISK进展队列GEO回末测序数据整理!G29)) -> Not IBD | S30: =IF(LOWER(TRIM(RISK进展队列GEO回末测序数据整理!H29))="not ibd","Not IBD",TRIM(RISK进展队列GEO回末测序数据整理!H29)) -> Not IBD | T30: =IF(RISK进展队列GEO回末测序数据整理!D29="女","女性",IF(RISK进展队列GEO回末测序数据整理!D29="男","男性",TRIM(RISK进展队列GEO回末测序数据整理!D29))) -> 女性 | U30: =RISK进展队列GEO回末测序数据整理!E29 -> 16.92 | V30: =RISK进展队列GEO回末测序数据整理!F29 -> A1b | W30: =IF(RISK进展队列GEO回末测序数据整理!I29="Macroscopic inflammation","Macro",IF(RISK进展队列GEO回末测序数据整理!I29="Microscopic inflammation","Micro",TRIM(RISK进展队列GEO回末测序数据整理!I29))) -> NA | X30: =IF(RISK进展队列GEO回末测序数据整理!J29=1,"Yes",IF(RISK进展队列GEO回末测序数据整理!J29=0,"No","N/A")) -> N/A | Y30: =IF(Q30="","",IF(COUNTIF($Q$3:Q30,Q30)=1,1,0)) -> 1 | Z30: =IF(Q30="","",IF(COUNTIFS($Q$3:Q30,Q30,$R$3:R30,R30)=1,1,0)) -> 1
A31: CD亚型 | B31: 患者数 | C31: CD内占比 | D31: 说明 | P31: =RISK进展队列GEO回末测序数据整理!A30 -> GSM1598436 | Q31: =RISK进展队列GEO回末测序数据整理!B30 -> CCFA_Risk_029 | R31: =IF(LOWER(TRIM(RISK进展队列GEO回末测序数据整理!G30))="not ibd","Not IBD",TRIM(RISK进展队列GEO回末测序数据整理!G30)) -> CD | S31: =IF(LOWER(TRIM(RISK进展队列GEO回末测序数据整理!H30))="not ibd","Not IBD",TRIM(RISK进展队列GEO回末测序数据整理!H30)) -> iCD | T31: =IF(RISK进展队列GEO回末测序数据整理!D30="女","女性",IF(RISK进展队列GEO回末测序数据整理!D30="男","男性",TRIM(RISK进展队列GEO回末测序数据整理!D30))) -> 女性 | U31: =RISK进展队列GEO回末测序数据整理!E30 -> 10.83 | V31: =RISK进展队列GEO回末测序数据整理!F30 -> A1b | W31: =IF(RISK进展队列GEO回末测序数据整理!I30="Macroscopic inflammation","Macro",IF(RISK进展队列GEO回末测序数据整理!I30="Microscopic inflammation","Micro",TRIM(RISK进展队列GEO回末测序数据整理!I30))) -> Macro | X31: =IF(RISK进展队列GEO回末测序数据整理!J30=1,"Yes",IF(RISK进展队列GEO回末测序数据整理!J30=0,"No","N/A")) -> No | Y31: =IF(Q31="","",IF(COUNTIF($Q$3:Q31,Q31)=1,1,0)) -> 1 | Z31: =IF(Q31="","",IF(COUNTIFS($Q$3:Q31,Q31,$R$3:R31,R31)=1,1,0)) -> 1
A32: iCD | B32: =COUNTIF($S$3:$S$324,A32) -> 163 | C32: =IFERROR(B32/$B$34,"") -> 0.74770642 | D32: 每名患者一个回肠样本 | P32: =RISK进展队列GEO回末测序数据整理!A31 -> GSM1598437 | Q32: =RISK进展队列GEO回末测序数据整理!B31 -> CCFA_Risk_030 | R32: =IF(LOWER(TRIM(RISK进展队列GEO回末测序数据整理!G31))="not ibd","Not IBD",TRIM(RISK进展队列GEO回末测序数据整理!G31)) -> CD | S32: =IF(LOWER(TRIM(RISK进展队列GEO回末测序数据整理!H31))="not ibd","Not IBD",TRIM(RISK进展队列GEO回末测序数据整理!H31)) -> iCD | T32: =IF(RISK进展队列GEO回末测序数据整理!D31="女","女性",IF(RISK进展队列GEO回末测序数据整理!D31="男","男性",TRIM(RISK进展队列GEO回末测序数据整理!D31))) -> 男性 | U32: =RISK进展队列GEO回末测序数据整理!E31 -> 10.75 | V32: =RISK进展队列GEO回末测序数据整理!F31 -> A1b | W32: =IF(RISK进展队列GEO回末测序数据整理!I31="Macroscopic inflammation","Macro",IF(RISK进展队列GEO回末测序数据整理!I31="Microscopic inflammation","Micro",TRIM(RISK进展队列GEO回末测序数据整理!I31))) -> Macro | X32: =IF(RISK进展队列GEO回末测序数据整理!J31=1,"Yes",IF(RISK进展队列GEO回末测序数据整理!J31=0,"No","N/A")) -> No | Y32: =IF(Q32="","",IF(COUNTIF($Q$3:Q32,Q32)=1,1,0)) -> 1 | Z32: =IF(Q32="","",IF(COUNTIFS($Q$3:Q32,Q32,$R$3:R32,R32)=1,1,0)) -> 1
A33: cCD | B33: =COUNTIF($S$3:$S$324,A33) -> 55 | C33: =IFERROR(B33/$B$34,"") -> 0.25229358 | D33: 每名患者一个回肠样本 | P33: =RISK进展队列GEO回末测序数据整理!A32 -> GSM1598438 | Q33: =RISK进展队列GEO回末测序数据整理!B32 -> CCFA_Risk_031 | R33: =IF(LOWER(TRIM(RISK进展队列GEO回末测序数据整理!G32))="not ibd","Not IBD",TRIM(RISK进展队列GEO回末测序数据整理!G32)) -> Not IBD | S33: =IF(LOWER(TRIM(RISK进展队列GEO回末测序数据整理!H32))="not ibd","Not IBD",TRIM(RISK进展队列GEO回末测序数据整理!H32)) -> Not IBD | T33: =IF(RISK进展队列GEO回末测序数据整理!D32="女","女性",IF(RISK进展队列GEO回末测序数据整理!D32="男","男性",TRIM(RISK进展队列GEO回末测序数据整理!D32))) -> 女性 | U33: =RISK进展队列GEO回末测序数据整理!E32 -> 12.5 | V33: =RISK进展队列GEO回末测序数据整理!F32 -> A1b | W33: =IF(RISK进展队列GEO回末测序数据整理!I32="Macroscopic inflammation","Macro",IF(RISK进展队列GEO回末测序数据整理!I32="Microscopic inflammation","Micro",TRIM(RISK进展队列GEO回末测序数据整理!I32))) -> NA | X33: =IF(RISK进展队列GEO回末测序数据整理!J32=1,"Yes",IF(RISK进展队列GEO回末测序数据整理!J32=0,"No","N/A")) -> N/A | Y33: =IF(Q33="","",IF(COUNTIF($Q$3:Q33,Q33)=1,1,0)) -> 1 | Z33: =IF(Q33="","",IF(COUNTIFS($Q$3:Q33,Q33,$R$3:R33,R33)=1,1,0)) -> 1
A34: CD合计 | B34: =SUM(B32:B33) -> 218 | C34: =SUM(C32:C33) -> 1 | P34: =RISK进展队列GEO回末测序数据整理!A33 -> GSM1598439 | Q34: =RISK进展队列GEO回末测序数据整理!B33 -> CCFA_Risk_032 | R34: =IF(LOWER(TRIM(RISK进展队列GEO回末测序数据整理!G33))="not ibd","Not IBD",TRIM(RISK进展队列GEO回末测序数据整理!G33)) -> CD | S34: =IF(LOWER(TRIM(RISK进展队列GEO回末测序数据整理!H33))="not ibd","Not IBD",TRIM(RISK进展队列GEO回末测序数据整理!H33)) -> iCD | T34: =IF(RISK进展队列GEO回末测序数据整理!D33="女","女性",IF(RISK进展队列GEO回末测序数据整理!D33="男","男性",TRIM(RISK进展队列GEO回末测序数据整理!D33))) -> 女性 | U34: =RISK进展队列GEO回末测序数据整理!E33 -> 8.67 | V34: =RISK进展队列GEO回末测序数据整理!F33 -> A1a | W34: =IF(RISK进展队列GEO回末测序数据整理!I33="Macroscopic inflammation","Macro",IF(RISK进展队列GEO回末测序数据整理!I33="Microscopic inflammation","Micro",TRIM(RISK进展队列GEO回末测序数据整理!I33))) -> Macro | X34: =IF(RISK进展队列GEO回末测序数据整理!J33=1,"Yes",IF(RISK进展队列GEO回末测序数据整理!J33=0,"No","N/A")) -> No | Y34: =IF(Q34="","",IF(COUNTIF($Q$3:Q34,Q34)=1,1,0)) -> 1 | Z34: =IF(Q34="","",IF(COUNTIFS($Q$3:Q34,Q34,$R$3:R34,R34)=1,1,0)) -> 1
P35: =RISK进展队列GEO回末测序数据整理!A34 -> GSM1598440 | Q35: =RISK进展队列GEO回末测序数据整理!B34 -> CCFA_Risk_033 | R35: =IF(LOWER(TRIM(RISK进展队列GEO回末测序数据整理!G34))="not ibd","Not IBD",TRIM(RISK进展队列GEO回末测序数据整理!G34)) -> Not IBD | S35: =IF(LOWER(TRIM(RISK进展队列GEO回末测序数据整理!H34))="not ibd","Not IBD",TRIM(RISK进展队列GEO回末测序数据整理!H34)) -> Not IBD | T35: =IF(RISK进展队列GEO回末测序数据整理!D34="女","女性",IF(RISK进展队列GEO回末测序数据整理!D34="男","男性",TRIM(RISK进展队列GEO回末测序数据整理!D34))) -> 男性 | U35: =RISK进展队列GEO回末测序数据整理!E34 -> 9.33 | V35: =RISK进展队列GEO回末测序数据整理!F34 -> A1a | W35: =IF(RISK进展队列GEO回末测序数据整理!I34="Macroscopic inflammation","Macro",IF(RISK进展队列GEO回末测序数据整理!I34="Microscopic inflammation","Micro",TRIM(RISK进展队列GEO回末测序数据整理!I34))) -> NA | X35: =IF(RISK进展队列GEO回末测序数据整理!J34=1,"Yes",IF(RISK进展队列GEO回末测序数据整理!J34=0,"No","N/A")) -> N/A | Y35: =IF(Q35="","",IF(COUNTIF($Q$3:Q35,Q35)=1,1,0)) -> 1 | Z35: =IF(Q35="","",IF(COUNTIFS($Q$3:Q35,Q35,$R$3:R35,R35)=1,1,0)) -> 1
A36: 5. Paris年龄分层（患者级） | P36: =RISK进展队列GEO回末测序数据整理!A35 -> GSM1598441 | Q36: =RISK进展队列GEO回末测序数据整理!B35 -> CCFA_Risk_034 | R36: =IF(LOWER(TRIM(RISK进展队列GEO回末测序数据整理!G35))="not ibd","Not IBD",TRIM(RISK进展队列GEO回末测序数据整理!G35)) -> Not IBD | S36: =IF(LOWER(TRIM(RISK进展队列GEO回末测序数据整理!H35))="not ibd","Not IBD",TRIM(RISK进展队列GEO回末测序数据整理!H35)) -> Not IBD | T36: =IF(RISK进展队列GEO回末测序数据整理!D35="女","女性",IF(RISK进展队列GEO回末测序数据整理!D35="男","男性",TRIM(RISK进展队列GEO回末测序数据整理!D35))) -> 男性 | U36: =RISK进展队列GEO回末测序数据整理!E35 -> 7.75 | V36: =RISK进展队列GEO回末测序数据整理!F35 -> A1a | W36: =IF(RISK进展队列GEO回末测序数据整理!I35="Macroscopic inflammation","Macro",IF(RISK进展队列GEO回末测序数据整理!I35="Microscopic inflammation","Micro",TRIM(RISK进展队列GEO回末测序数据整理!I35))) -> NA | X36: =IF(RISK进展队列GEO回末测序数据整理!J35=1,"Yes",IF(RISK进展队列GEO回末测序数据整理!J35=0,"No","N/A")) -> N/A | Y36: =IF(Q36="","",IF(COUNTIF($Q$3:Q36,Q36)=1,1,0)) -> 1 | Z36: =IF(Q36="","",IF(COUNTIFS($Q$3:Q36,Q36,$R$3:R36,R36)=1,1,0)) -> 1
A37: Paris分层 | B37: 患者数 | C37: 患者占比 | D37: 说明 | P37: =RISK进展队列GEO回末测序数据整理!A36 -> GSM1598442 | Q37: =RISK进展队列GEO回末测序数据整理!B36 -> CCFA_Risk_035 | R37: =IF(LOWER(TRIM(RISK进展队列GEO回末测序数据整理!G36))="not ibd","Not IBD",TRIM(RISK进展队列GEO回末测序数据整理!G36)) -> Not IBD | S37: =IF(LOWER(TRIM(RISK进展队列GEO回末测序数据整理!H36))="not ibd","Not IBD",TRIM(RISK进展队列GEO回末测序数据整理!H36)) -> Not IBD | T37: =IF(RISK进展队列GEO回末测序数据整理!D36="女","女性",IF(RISK进展队列GEO回末测序数据整理!D36="男","男性",TRIM(RISK进展队列GEO回末测序数据整理!D36))) -> 男性 | U37: =RISK进展队列GEO回末测序数据整理!E36 -> 11.5 | V37: =RISK进展队列GEO回末测序数据整理!F36 -> A1b | W37: =IF(RISK进展队列GEO回末测序数据整理!I36="Macroscopic inflammation","Macro",IF(RISK进展队列GEO回末测序数据整理!I36="Microscopic inflammation","Micro",TRIM(RISK进展队列GEO回末测序数据整理!I36))) -> NA | X37: =IF(RISK进展队列GEO回末测序数据整理!J36=1,"Yes",IF(RISK进展队列GEO回末测序数据整理!J36=0,"No","N/A")) -> N/A | Y37: =IF(Q37="","",IF(COUNTIF($Q$3:Q37,Q37)=1,1,0)) -> 1 | Z37: =IF(Q37="","",IF(COUNTIFS($Q$3:Q37,Q37,$R$3:R37,R37)=1,1,0)) -> 1
A38: A1a | B38: =COUNTIF($V$3:$V$324,A38) -> 90 | C38: =IFERROR(B38/$B$40,"") -> 0.27950311 | D38: 全队列 | P38: =RISK进展队列GEO回末测序数据整理!A37 -> GSM1598443 | Q38: =RISK进展队列GEO回末测序数据整理!B37 -> CCFA_Risk_036 | R38: =IF(LOWER(TRIM(RISK进展队列GEO回末测序数据整理!G37))="not ibd","Not IBD",TRIM(RISK进展队列GEO回末测序数据整理!G37)) -> Not IBD | S38: =IF(LOWER(TRIM(RISK进展队列GEO回末测序数据整理!H37))="not ibd","Not IBD",TRIM(RISK进展队列GEO回末测序数据整理!H37)) -> Not IBD | T38: =IF(RISK进展队列GEO回末测序数据整理!D37="女","女性",IF(RISK进展队列GEO回末测序数据整理!D37="男","男性",TRIM(RISK进展队列GEO回末测序数据整理!D37))) -> 男性 | U38: =RISK进展队列GEO回末测序数据整理!E37 -> 10.5 | V38: =RISK进展队列GEO回末测序数据整理!F37 -> A1b | W38: =IF(RISK进展队列GEO回末测序数据整理!I37="Macroscopic inflammation","Macro",IF(RISK进展队列GEO回末测序数据整理!I37="Microscopic inflammation","Micro",TRIM(RISK进展队列GEO回末测序数据整理!I37))) -> NA | X38: =IF(RISK进展队列GEO回末测序数据整理!J37=1,"Yes",IF(RISK进展队列GEO回末测序数据整理!J37=0,"No","N/A")) -> N/A | Y38: =IF(Q38="","",IF(COUNTIF($Q$3:Q38,Q38)=1,1,0)) -> 1 | Z38: =IF(Q38="","",IF(COUNTIFS($Q$3:Q38,Q38,$R$3:R38,R38)=1,1,0)) -> 1
A39: A1b | B39: =COUNTIF($V$3:$V$324,A39) -> 232 | C39: =IFERROR(B39/$B$40,"") -> 0.72049689 | D39: 全队列 | P39: =RISK进展队列GEO回末测序数据整理!A38 -> GSM1598444 | Q39: =RISK进展队列GEO回末测序数据整理!B38 -> CCFA_Risk_037 | R39: =IF(LOWER(TRIM(RISK进展队列GEO回末测序数据整理!G38))="not ibd","Not IBD",TRIM(RISK进展队列GEO回末测序数据整理!G38)) -> CD | S39: =IF(LOWER(TRIM(RISK进展队列GEO回末测序数据整理!H38))="not ibd","Not IBD",TRIM(RISK进展队列GEO回末测序数据整理!H38)) -> iCD | T39: =IF(RISK进展队列GEO回末测序数据整理!D38="女","女性",IF(RISK进展队列GEO回末测序数据整理!D38="男","男性",TRIM(RISK进展队列GEO回末测序数据整理!D38))) -> 男性 | U39: =RISK进展队列GEO回末测序数据整理!E38 -> 10.5 | V39: =RISK进展队列GEO回末测序数据整理!F38 -> A1b | W39: =IF(RISK进展队列GEO回末测序数据整理!I38="Macroscopic inflammation","Macro",IF(RISK进展队列GEO回末测序数据整理!I38="Microscopic inflammation","Micro",TRIM(RISK进展队列GEO回末测序数据整理!I38))) -> Macro | X39: =IF(RISK进展队列GEO回末测序数据整理!J38=1,"Yes",IF(RISK进展队列GEO回末测序数据整理!J38=0,"No","N/A")) -> Yes | Y39: =IF(Q39="","",IF(COUNTIF($Q$3:Q39,Q39)=1,1,0)) -> 1 | Z39: =IF(Q39="","",IF(COUNTIFS($Q$3:Q39,Q39,$R$3:R39,R39)=1,1,0)) -> 1
A40: 合计 | B40: =SUM(B38:B39) -> 322 | C40: =SUM(C38:C39) -> 1 | P40: =RISK进展队列GEO回末测序数据整理!A39 -> GSM1598445 | Q40: =RISK进展队列GEO回末测序数据整理!B39 -> CCFA_Risk_038 | R40: =IF(LOWER(TRIM(RISK进展队列GEO回末测序数据整理!G39))="not ibd","Not IBD",TRIM(RISK进展队列GEO回末测序数据整理!G39)) -> Not IBD | S40: =IF(LOWER(TRIM(RISK进展队列GEO回末测序数据整理!H39))="not ibd","Not IBD",TRIM(RISK进展队列GEO回末测序数据整理!H39)) -> Not IBD | T40: =IF(RISK进展队列GEO回末测序数据整理!D39="女","女性",IF(RISK进展队列GEO回末测序数据整理!D39="男","男性",TRIM(RISK进展队列GEO回末测序数据整理!D39))) -> 男性 | U40: =RISK进展队列GEO回末测序数据整理!E39 -> 8.67 | V40: =RISK进展队列GEO回末测序数据整理!F39 -> A1a | W40: =IF(RISK进展队列GEO回末测序数据整理!I39="Macroscopic inflammation","Macro",IF(RISK进展队列GEO回末测序数据整理!I39="Microscopic inflammation","Micro",TRIM(RISK进展队列GEO回末测序数据整理!I39))) -> NA | X40: =IF(RISK进展队列GEO回末测序数据整理!J39=1,"Yes",IF(RISK进展队列GEO回末测序数据整理!J39=0,"No","N/A")) -> N/A | Y40: =IF(Q40="","",IF(COUNTIF($Q$3:Q40,Q40)=1,1,0)) -> 1 | Z40: =IF(Q40="","",IF(COUNTIFS($Q$3:Q40,Q40,$R$3:R40,R40)=1,1,0)) -> 1
...
